2022-08-20 13:45:14,315 DEBUG    root            Loaded Command Group: ['gcloud', 'container', 'clusters']
2022-08-20 13:45:14,320 DEBUG    root            Loaded Command Group: ['gcloud', 'container', 'clusters', 'create']
2022-08-20 13:45:14,337 DEBUG    root            Running [gcloud.container.clusters.create] with arguments: [--cluster-ipv4-cidr: "10.82.0.0/14", --enable-ip-alias: "True", --node-taints: "OrderedDict([('node.cilium.io/agent-not-ready', 'true:NoExecute')])", --services-ipv4-cidr: "10.86.0.0/20", --zone: "europe-central2-a", NAME: "bmutziu-16662"]
2022-08-20 13:45:14,340 INFO     ___FILE_ONLY___ Note: The Pod address range limits the maximum size of the cluster. Please refer to https://cloud.google.com/kubernetes-engine/docs/how-to/flexible-pod-cidr to learn how to optimize IP address allocation.

2022-08-20 13:45:14,442 DEBUG    urllib3.connectionpool Starting new HTTPS connection (1): container.googleapis.com:443
2022-08-20 13:45:16,458 DEBUG    urllib3.connectionpool https://container.googleapis.com:443 "POST /v1/projects/cilium-20220820000618/locations/europe-central2-a/clusters?alt=json HTTP/1.1" 400 None
2022-08-20 13:45:16,465 DEBUG    root            (gcloud.container.clusters.create) ResponseError: code=400, message="10.82.0.0/14" is not aligned to a CIDR block. Did you mean "10.80.0.0/14"?.
Traceback (most recent call last):
  File "/opt/homebrew/Caskroom/google-cloud-sdk/latest/google-cloud-sdk/lib/surface/container/clusters/create.py", line 1142, in Run
    operation_ref = adapter.CreateCluster(cluster_ref, options)
  File "/opt/homebrew/Caskroom/google-cloud-sdk/latest/google-cloud-sdk/lib/googlecloudsdk/api_lib/container/api_adapter.py", line 2235, in CreateCluster
    operation = self.client.projects_locations_clusters.Create(req)
  File "/opt/homebrew/Caskroom/google-cloud-sdk/latest/google-cloud-sdk/lib/googlecloudsdk/third_party/apis/container/v1/container_v1_client.py", line 493, in Create
    return self._RunMethod(
  File "/opt/homebrew/Caskroom/google-cloud-sdk/latest/google-cloud-sdk/lib/third_party/apitools/base/py/base_api.py", line 737, in _RunMethod
    return self.ProcessHttpResponse(method_config, http_response, request)
  File "/opt/homebrew/Caskroom/google-cloud-sdk/latest/google-cloud-sdk/lib/third_party/apitools/base/py/base_api.py", line 743, in ProcessHttpResponse
    self.__ProcessHttpResponse(method_config, http_response, request))
  File "/opt/homebrew/Caskroom/google-cloud-sdk/latest/google-cloud-sdk/lib/third_party/apitools/base/py/base_api.py", line 609, in __ProcessHttpResponse
    raise exceptions.HttpError.FromResponse(
apitools.base.py.exceptions.HttpBadRequestError: HttpError accessing <https://container.googleapis.com/v1/projects/cilium-20220820000618/locations/europe-central2-a/clusters?alt=json>: response: <{'vary': 'Origin, X-Origin, Referer', 'content-type': 'application/json; charset=UTF-8', 'content-encoding': 'gzip', 'date': 'Sat, 20 Aug 2022 10:45:16 GMT', 'server': 'ESF', 'cache-control': 'private', 'x-xss-protection': '0', 'x-frame-options': 'SAMEORIGIN', 'x-content-type-options': 'nosniff', 'alt-svc': 'h3=":443"; ma=2592000,h3-29=":443"; ma=2592000,h3-Q050=":443"; ma=2592000,h3-Q046=":443"; ma=2592000,h3-Q043=":443"; ma=2592000,quic=":443"; ma=2592000; v="46,43"', 'transfer-encoding': 'chunked', 'status': 400}>, content <{
  "error": {
    "code": 400,
    "message": "\"10.82.0.0/14\" is not aligned to a CIDR block. Did you mean \"10.80.0.0/14\"?.",
    "status": "INVALID_ARGUMENT"
  }
}
>

During handling of the above exception, another exception occurred:

Traceback (most recent call last):
  File "/opt/homebrew/Caskroom/google-cloud-sdk/latest/google-cloud-sdk/lib/googlecloudsdk/calliope/cli.py", line 987, in Execute
    resources = calliope_command.Run(cli=self, args=args)
  File "/opt/homebrew/Caskroom/google-cloud-sdk/latest/google-cloud-sdk/lib/googlecloudsdk/calliope/backend.py", line 809, in Run
    resources = command_instance.Run(args)
  File "/opt/homebrew/Caskroom/google-cloud-sdk/latest/google-cloud-sdk/lib/surface/container/clusters/create.py", line 1153, in Run
    raise exceptions.HttpException(error, util.HTTP_ERROR_FORMAT)
googlecloudsdk.calliope.exceptions.HttpException: ResponseError: code=400, message="10.82.0.0/14" is not aligned to a CIDR block. Did you mean "10.80.0.0/14"?.
2022-08-20 13:45:16,472 ERROR    root            (gcloud.container.clusters.create) ResponseError: code=400, message="10.82.0.0/14" is not aligned to a CIDR block. Did you mean "10.80.0.0/14"?.
